Traceback (most recent call last):
  File "/home/ryan/miniconda3/envs/nbdev/lib/python3.10/site-packages/jupyter_cache/executors/utils.py", line 58, in single_nb_execution
    executenb(
  File "/home/ryan/miniconda3/envs/nbdev/lib/python3.10/site-packages/nbclient/client.py", line 1305, in execute
    return NotebookClient(nb=nb, resources=resources, km=km, **kwargs).execute()
  File "/home/ryan/miniconda3/envs/nbdev/lib/python3.10/site-packages/jupyter_core/utils/__init__.py", line 173, in wrapped
    return loop.run_until_complete(inner)
  File "/home/ryan/miniconda3/envs/nbdev/lib/python3.10/asyncio/base_events.py", line 649, in run_until_complete
    return future.result()
  File "/home/ryan/miniconda3/envs/nbdev/lib/python3.10/site-packages/nbclient/client.py", line 705, in async_execute
    await self.async_execute_cell(
  File "/home/ryan/miniconda3/envs/nbdev/lib/python3.10/site-packages/nbclient/client.py", line 1058, in async_execute_cell
    await self._check_raise_for_error(cell, cell_index, exec_reply)
  File "/home/ryan/miniconda3/envs/nbdev/lib/python3.10/site-packages/nbclient/client.py", line 914, in _check_raise_for_error
    raise CellExecutionError.from_cell_and_msg(cell, exec_reply_content)
nbclient.exceptions.CellExecutionError: An error occurred while executing the following cell:
------------------
t = a0 + a1*oring[:, 1];
y = oring[:, 2]
J = 1/len(data)*np.sum(-y*np.log(sigma(t))-(1-y)*np.log(1-sigma(t)))
J
------------------


[0;31m---------------------------------------------------------------------------[0m
[0;31mNameError[0m                                 Traceback (most recent call last)
Cell [0;32mIn[6], line 3[0m
[1;32m      1[0m t [38;5;241m=[39m a0 [38;5;241m+[39m a1[38;5;241m*[39moring[:, [38;5;241m1[39m];
[1;32m      2[0m y [38;5;241m=[39m oring[:, [38;5;241m2[39m]
[0;32m----> 3[0m J [38;5;241m=[39m [38;5;241m1[39m[38;5;241m/[39m[38;5;28mlen[39m([43mdata[49m)[38;5;241m*[39mnp[38;5;241m.[39msum([38;5;241m-[39my[38;5;241m*[39mnp[38;5;241m.[39mlog(sigma(t))[38;5;241m-[39m([38;5;241m1[39m[38;5;241m-[39my)[38;5;241m*[39mnp[38;5;241m.[39mlog([38;5;241m1[39m[38;5;241m-[39msigma(t)))
[1;32m      4[0m J

[0;31mNameError[0m: name 'data' is not defined

